<?xml version="1.0" ?>
<sdf version="1.8">
  <model name="fendt" canonical_link="base">
    <static> true </static>
    <link name="base">
      <pose relative_to="__model__"> 0 0 0 0 0 0 </pose>
      <visual name="fendt_visual">
        <laser_retro>1</laser_retro>
        <geometry>
         <mesh>
            <uri>models://meshes/fendt_split/body.dae</uri>
          <scale>1 1 1</scale>
         </mesh>
       </geometry>
        <material>
          <ambient>0.1 0.1 0.1</ambient>
          <diffuse>0.1 0.1 0.1</diffuse>
          <specular>0.1 0.1 0.1</specular>
        </material>
      </visual>
      <collision name="fendt_collision">
        <pose>0 0 0.5 0 0 0</pose>
        <geometry>
          <box>1 1 1</box>
        </geometry>
      </collision>
    </link> 
    <link name="left_wheel">
      <pose relative_to="__model__"> 0 0 0 0 0 0 </pose>
      <visual name="fendt_left_wheel_visual">
        <laser_retro>1</laser_retro>
        <geometry>
         <mesh>
            <uri>models://meshes/fendt_split/left_front_wheel.dae</uri>
          <scale>1 1 1</scale>
         </mesh>
       </geometry>
        <material>
          <ambient>0.2 0.1 0.1</ambient>
          <diffuse>0.3 0.1 0.1</diffuse>
          <specular>0.3 0.1 0.1</specular>
        </material>
      </visual>
    </link>
    <link name="right_wheel">
      <pose relative_to="__model__"> 0 0 0 0 0 0 </pose>
      <visual name="fendt_right_wheel_visual">
        <laser_retro>1</laser_retro>
        <geometry>
         <mesh>
            <uri>models://meshes/fendt_split/right_front_wheel.dae</uri>
          <scale>1 1 1</scale>
         </mesh>
       </geometry>
        <material>
          <ambient>0.2 0.1 0.1</ambient>
          <diffuse>0.3 0.1 0.1</diffuse>
          <specular>0.3 0.1 0.1</specular>
        </material>
      </visual>
    </link>
    <link name="forks">
      <pose relative_to="__model__"> 0 0 0 0 0 0 </pose>
      <visual name="fendt_forks_visual">
        <laser_retro>1</laser_retro>
        <geometry>
         <mesh>
            <uri>models://meshes/fendt_split/forks.dae</uri>
          <scale>1 1 1</scale>
         </mesh>
       </geometry>
        <material>
          <ambient>0.1 0.2 0.1</ambient>
          <diffuse>0.1 0.3 0.1</diffuse>
          <specular>0.1 0.3 0.1</specular>
        </material>
      </visual>
    </link>

    <joint name="left_wheel_joint" type="revolute">
      <pose relative_to="left_wheel">-1 -0.5 0 0 0 0 </pose>
      <parent>base</parent>
      <child>left_wheel</child>
      <axis>
        <xyz expesses_in="__model__">0 0 1</xyz>
        <limit>
          <lower>-0.5</lower>
          <upper>0.5</upper>
        </limit>
      </axis>
      <joint_move_group> front_wheels </joint_move_group>
    </joint>

    <joint name="right_wheel_joint" type="revolute">
      <pose relative_to="right_wheel">-1 0.5 0 0 0 0 </pose>
      <parent>base</parent>
      <child>right_wheel</child>
      <axis>
        <xyz expesses_in="__model__">0 0 1</xyz>
        <limit>
          <lower>-0.5</lower>
          <upper>0.5</upper>
        </limit>
      </axis>
      <joint_move_group> front_wheels </joint_move_group>
    </joint>

    <joint name="forks_joint" type="revolute">
      <pose relative_to="forks"> -0.35 0 1 0 0 0</pose>
      <parent>base</parent>
      <child>forks</child>
      <axis>
        <xyz expesses_in="__model__">0 1 0</xyz>
        <limit>
          <lower>-1</lower>
          <upper>1</upper>
        </limit>
      </axis>
      <joint_move_group> forks </joint_move_group>
    </joint>

    <plugin
      filename="libjoint_random_mover.so"
      name="lidar_sim::joint_random_mover">
      <joint_name>forks_joint</joint_name>
      <joint_move_group>forks</joint_move_group>
    </plugin>
    <plugin
      filename="libjoint_random_mover.so"
      name="lidar_sim::joint_random_mover">
      <joint_name>left_wheel_joint</joint_name>
      <joint_name>right_wheel_joint</joint_name>
      <joint_move_group>front_wheels</joint_move_group>
    </plugin>

    <plugin
      filename="librandom_mover.so"
      name="lidar_sim::random_mover">
      <move_group>target</move_group>
    </plugin>
  </model>
</sdf>
